2025-06-20 19:23:37,555 [INFO] Loading model from: /Users/aviv/Library/Mobile Documents/com~apple~CloudDocs/study/MLOps_Group_Project/models/logistic_regression.pkl
2025-06-20 19:23:37,555 [INFO] Loading test data from: /Users/aviv/Library/Mobile Documents/com~apple~CloudDocs/study/MLOps_Group_Project/data/processed/training_data
Traceback (most recent call last):
  File [35m"/Users/aviv/Library/Mobile Documents/com~apple~CloudDocs/study/MLOps_Group_Project/src/mlops/evaluation/run.py"[0m, line [35m92[0m, in [35m<module>[0m
    [31mrun_evaluation[0m[1;31m(args.model_artifact, args.test_data_path)[0m
    [31m~~~~~~~~~~~~~~[0m[1;31m^^^^^^^^^^^^^^^^^^^^^^^^^^^^^^^^^^^^^^^^^^[0m
  File [35m"/Users/aviv/Library/Mobile Documents/com~apple~CloudDocs/study/MLOps_Group_Project/src/mlops/evaluation/run.py"[0m, line [35m49[0m, in [35mrun_evaluation[0m
    evaluator = ModelEvaluator(
        model_path=model_artifact_path,
        test_data_dir=test_data_dir,
        config=config
    )
[1;35mTypeError[0m: [35mModelEvaluator.__init__() got an unexpected keyword argument 'model_path'[0m
