✅ Started W&B orchestrator run: orchestrator_20250620_191013
✅ Set MLflow experiment to: 'MLOps-Group-Project-Experiment'
▶️  Running step: 'data_load'...
2025/06/20 19:10:16 INFO mlflow.utils.conda: Conda environment mlflow-b38cc610a566358f4ff450976fe6275733f34b85 already exists.
2025/06/20 19:10:16 INFO mlflow.projects.utils: === Created directory /var/folders/8m/nc66qdpd59zc9q76n8rk5d9m0000gn/T/tmpqjij5s8i for downloading remote URIs passed to arguments of type 'path' ===
2025/06/20 19:10:16 INFO mlflow.projects.backend.local: === Running command 'source /Users/aviv/Applications/anaconda3/bin/../etc/profile.d/conda.sh && conda activate mlflow-b38cc610a566358f4ff450976fe6275733f34b85 1>&2 && python3 src/mlops/data_load/run.py' in run with ID '08b33972c6bc4040876672f1ad6e4570' ===
2025/06/20 19:10:41 INFO mlflow.projects: === Run (ID '08b33972c6bc4040876672f1ad6e4570') succeeded ===
✅ Step 'data_load' finished.
▶️  Running step: 'data_validation'...
2025/06/20 19:10:42 INFO mlflow.utils.conda: Conda environment mlflow-b38cc610a566358f4ff450976fe6275733f34b85 already exists.
2025/06/20 19:10:42 INFO mlflow.projects.utils: === Created directory /var/folders/8m/nc66qdpd59zc9q76n8rk5d9m0000gn/T/tmpa8w5ykix for downloading remote URIs passed to arguments of type 'path' ===
2025/06/20 19:10:42 INFO mlflow.projects.backend.local: === Running command 'source /Users/aviv/Applications/anaconda3/bin/../etc/profile.d/conda.sh && conda activate mlflow-b38cc610a566358f4ff450976fe6275733f34b85 1>&2 && python3 src/mlops/data_validation/run.py --input-artifact '/Users/aviv/Library/Mobile Documents/com~apple~CloudDocs/study/MLOps_Group_Project/data/raw/raw_data.csv'' in run with ID '045cce58b9a24065b5532d62fd1f5399' ===
Error executing job with overrides: []
Traceback (most recent call last):
  File "/Users/aviv/Library/Mobile Documents/com~apple~CloudDocs/study/MLOps_Group_Project/main.py", line 130, in main
    mlflow.run(".", entry_point=step, parameters=params)
    ~~~~~~~~~~^^^^^^^^^^^^^^^^^^^^^^^^^^^^^^^^^^^^^^^^^^
  File "/Library/Frameworks/Python.framework/Versions/3.13/lib/python3.13/site-packages/mlflow/projects/__init__.py", line 374, in run
    _wait_for(submitted_run_obj)
    ~~~~~~~~~^^^^^^^^^^^^^^^^^^^
  File "/Library/Frameworks/Python.framework/Versions/3.13/lib/python3.13/site-packages/mlflow/projects/__init__.py", line 391, in _wait_for
    raise ExecutionException(f"Run (ID '{run_id}') failed")
mlflow.exceptions.ExecutionException: Run (ID '045cce58b9a24065b5532d62fd1f5399') failed

Set the environment variable HYDRA_FULL_ERROR=1 for a complete stack trace.
