✅ Started W&B orchestrator run: orchestrator_20250620_183905
▶️  Running step: 'data_load'...
Error executing job with overrides: []
Traceback (most recent call last):
  File "/Users/aviv/Library/Mobile Documents/com~apple~CloudDocs/study/MLOps_Group_Project/main.py", line 111, in main
    mlflow.run(step_dir, "main", parameters=params)
    ~~~~~~~~~~^^^^^^^^^^^^^^^^^^^^^^^^^^^^^^^^^^^^^
  File "/Library/Frameworks/Python.framework/Versions/3.13/lib/python3.13/site-packages/mlflow/projects/__init__.py", line 357, in run
    submitted_run_obj = _run(
        uri=uri,
    ...<12 lines>...
        docker_auth=docker_auth,
    )
  File "/Library/Frameworks/Python.framework/Versions/3.13/lib/python3.13/site-packages/mlflow/projects/__init__.py", line 110, in _run
    submitted_run = backend.run(
        uri,
    ...<5 lines>...
        experiment_id,
    )
  File "/Library/Frameworks/Python.framework/Versions/3.13/lib/python3.13/site-packages/mlflow/projects/backend/local.py", line 86, in run
    active_run = get_or_create_run(
        run_id, project_uri, experiment_id, work_dir, version, entry_point, params
    )
  File "/Library/Frameworks/Python.framework/Versions/3.13/lib/python3.13/site-packages/mlflow/projects/utils.py", line 256, in get_or_create_run
    return _create_run(uri, experiment_id, work_dir, version, entry_point, parameters)
  File "/Library/Frameworks/Python.framework/Versions/3.13/lib/python3.13/site-packages/mlflow/projects/utils.py", line 291, in _create_run
    active_run = tracking.MlflowClient().create_run(experiment_id=experiment_id, tags=tags)
  File "/Library/Frameworks/Python.framework/Versions/3.13/lib/python3.13/site-packages/mlflow/tracking/client.py", line 434, in create_run
    return self._tracking_client.create_run(experiment_id, start_time, tags, run_name)
           ~~~~~~~~~~~~~~~~~~~~~~~~~~~~~~~~^^^^^^^^^^^^^^^^^^^^^^^^^^^^^^^^^^^^^^^^^^^
  File "/Library/Frameworks/Python.framework/Versions/3.13/lib/python3.13/site-packages/mlflow/tracking/_tracking_service/client.py", line 161, in create_run
    return self.store.create_run(
           ~~~~~~~~~~~~~~~~~~~~~^
        experiment_id=experiment_id,
        ^^^^^^^^^^^^^^^^^^^^^^^^^^^^
    ...<3 lines>...
        run_name=run_name,
        ^^^^^^^^^^^^^^^^^^
    )
    ^
  File "/Library/Frameworks/Python.framework/Versions/3.13/lib/python3.13/site-packages/mlflow/store/tracking/file_store.py", line 662, in create_run
    experiment = self.get_experiment(experiment_id)
  File "/Library/Frameworks/Python.framework/Versions/3.13/lib/python3.13/site-packages/mlflow/store/tracking/file_store.py", line 471, in get_experiment
    experiment = self._get_experiment(experiment_id)
  File "/Library/Frameworks/Python.framework/Versions/3.13/lib/python3.13/site-packages/mlflow/store/tracking/file_store.py", line 441, in _get_experiment
    raise MlflowException(
    ...<2 lines>...
    )
mlflow.exceptions.MlflowException: Could not find experiment with ID 0

Set the environment variable HYDRA_FULL_ERROR=1 for a complete stack trace.
