2025-06-20 22:40:22,819 INFO    MainThread:83605 [wandb_setup.py:_flush():81] Current SDK version is 0.20.1
2025-06-20 22:40:22,819 INFO    MainThread:83605 [wandb_setup.py:_flush():81] Configure stats pid to 83605
2025-06-20 22:40:22,819 INFO    MainThread:83605 [wandb_setup.py:_flush():81] Loading settings from /Users/aviv/.config/wandb/settings
2025-06-20 22:40:22,819 INFO    MainThread:83605 [wandb_setup.py:_flush():81] Loading settings from /Users/aviv/Library/Mobile Documents/com~apple~CloudDocs/study/MLOps_Group_Project/wandb/settings
2025-06-20 22:40:22,819 INFO    MainThread:83605 [wandb_setup.py:_flush():81] Loading settings from environment variables
2025-06-20 22:40:22,820 INFO    MainThread:83605 [wandb_init.py:setup_run_log_directory():703] Logging user logs to /Users/aviv/Library/Mobile Documents/com~apple~CloudDocs/study/MLOps_Group_Project/wandb/run-20250620_224022-et35wpbk/logs/debug.log
2025-06-20 22:40:22,820 INFO    MainThread:83605 [wandb_init.py:setup_run_log_directory():704] Logging internal logs to /Users/aviv/Library/Mobile Documents/com~apple~CloudDocs/study/MLOps_Group_Project/wandb/run-20250620_224022-et35wpbk/logs/debug-internal.log
2025-06-20 22:40:22,820 INFO    MainThread:83605 [wandb_init.py:init():831] calling init triggers
2025-06-20 22:40:22,820 INFO    MainThread:83605 [wandb_init.py:init():836] wandb.init called with sweep_config: {}
config: {'_wandb': {}}
2025-06-20 22:40:22,820 INFO    MainThread:83605 [wandb_init.py:init():872] starting backend
2025-06-20 22:40:22,830 INFO    MainThread:83605 [wandb_init.py:init():875] sending inform_init request
2025-06-20 22:40:22,858 INFO    MainThread:83605 [wandb_init.py:init():883] backend started and connected
2025-06-20 22:40:22,861 INFO    MainThread:83605 [wandb_init.py:init():956] updated telemetry
2025-06-20 22:40:22,886 INFO    MainThread:83605 [wandb_init.py:init():980] communicating run to backend with 90.0 second timeout
2025-06-20 22:40:24,871 INFO    Thread-1 (wrapped_target):83605 [retry.py:__call__():173] [no run ID] Retry attempt failed:
Traceback (most recent call last):
  File "/Library/Frameworks/Python.framework/Versions/3.13/lib/python3.13/site-packages/urllib3/connection.py", line 198, in _new_conn
    sock = connection.create_connection(
        (self._dns_host, self.port),
    ...<2 lines>...
        socket_options=self.socket_options,
    )
  File "/Library/Frameworks/Python.framework/Versions/3.13/lib/python3.13/site-packages/urllib3/util/connection.py", line 85, in create_connection
    raise err
  File "/Library/Frameworks/Python.framework/Versions/3.13/lib/python3.13/site-packages/urllib3/util/connection.py", line 73, in create_connection
    sock.connect(sa)
    ~~~~~~~~~~~~^^^^
OSError: [Errno 51] Network is unreachable

The above exception was the direct cause of the following exception:

Traceback (most recent call last):
  File "/Library/Frameworks/Python.framework/Versions/3.13/lib/python3.13/site-packages/urllib3/connectionpool.py", line 787, in urlopen
    response = self._make_request(
        conn,
    ...<10 lines>...
        **response_kw,
    )
  File "/Library/Frameworks/Python.framework/Versions/3.13/lib/python3.13/site-packages/urllib3/connectionpool.py", line 488, in _make_request
    raise new_e
  File "/Library/Frameworks/Python.framework/Versions/3.13/lib/python3.13/site-packages/urllib3/connectionpool.py", line 464, in _make_request
    self._validate_conn(conn)
    ~~~~~~~~~~~~~~~~~~~^^^^^^
  File "/Library/Frameworks/Python.framework/Versions/3.13/lib/python3.13/site-packages/urllib3/connectionpool.py", line 1093, in _validate_conn
    conn.connect()
    ~~~~~~~~~~~~^^
  File "/Library/Frameworks/Python.framework/Versions/3.13/lib/python3.13/site-packages/urllib3/connection.py", line 704, in connect
    self.sock = sock = self._new_conn()
                       ~~~~~~~~~~~~~~^^
  File "/Library/Frameworks/Python.framework/Versions/3.13/lib/python3.13/site-packages/urllib3/connection.py", line 213, in _new_conn
    raise NewConnectionError(
        self, f"Failed to establish a new connection: {e}"
    ) from e
urllib3.exceptions.NewConnectionError: <urllib3.connection.HTTPSConnection object at 0x1339aca50>: Failed to establish a new connection: [Errno 51] Network is unreachable

The above exception was the direct cause of the following exception:

Traceback (most recent call last):
  File "/Library/Frameworks/Python.framework/Versions/3.13/lib/python3.13/site-packages/requests/adapters.py", line 667, in send
    resp = conn.urlopen(
        method=request.method,
    ...<9 lines>...
        chunked=chunked,
    )
  File "/Library/Frameworks/Python.framework/Versions/3.13/lib/python3.13/site-packages/urllib3/connectionpool.py", line 841, in urlopen
    retries = retries.increment(
        method, url, error=new_e, _pool=self, _stacktrace=sys.exc_info()[2]
    )
  File "/Library/Frameworks/Python.framework/Versions/3.13/lib/python3.13/site-packages/urllib3/util/retry.py", line 519, in increment
    raise MaxRetryError(_pool, url, reason) from reason  # type: ignore[arg-type]
    ^^^^^^^^^^^^^^^^^^^^^^^^^^^^^^^^^^^^^^^^^^^^^^^^^^^
urllib3.exceptions.MaxRetryError: HTTPSConnectionPool(host='api.wandb.ai', port=443): Max retries exceeded with url: /graphql (Caused by NewConnectionError('<urllib3.connection.HTTPSConnection object at 0x1339aca50>: Failed to establish a new connection: [Errno 51] Network is unreachable'))

During handling of the above exception, another exception occurred:

Traceback (most recent call last):
  File "/Library/Frameworks/Python.framework/Versions/3.13/lib/python3.13/site-packages/wandb/sdk/lib/retry.py", line 134, in __call__
    result = self._call_fn(*args, **kwargs)
  File "/Library/Frameworks/Python.framework/Versions/3.13/lib/python3.13/site-packages/wandb/sdk/internal/internal_api.py", line 396, in execute
    return self.client.execute(*args, **kwargs)  # type: ignore
           ~~~~~~~~~~~~~~~~~~~^^^^^^^^^^^^^^^^^
  File "/Library/Frameworks/Python.framework/Versions/3.13/lib/python3.13/site-packages/wandb/vendor/gql-0.2.0/wandb_gql/client.py", line 52, in execute
    result = self._get_result(document, *args, **kwargs)
  File "/Library/Frameworks/Python.framework/Versions/3.13/lib/python3.13/site-packages/wandb/vendor/gql-0.2.0/wandb_gql/client.py", line 60, in _get_result
    return self.transport.execute(document, *args, **kwargs)
           ~~~~~~~~~~~~~~~~~~~~~~^^^^^^^^^^^^^^^^^^^^^^^^^^^
  File "/Library/Frameworks/Python.framework/Versions/3.13/lib/python3.13/site-packages/wandb/sdk/lib/gql_request.py", line 58, in execute
    request = self.session.post(self.url, **post_args)
  File "/Library/Frameworks/Python.framework/Versions/3.13/lib/python3.13/site-packages/requests/sessions.py", line 637, in post
    return self.request("POST", url, data=data, json=json, **kwargs)
           ~~~~~~~~~~~~^^^^^^^^^^^^^^^^^^^^^^^^^^^^^^^^^^^^^^^^^^^^^
  File "/Library/Frameworks/Python.framework/Versions/3.13/lib/python3.13/site-packages/requests/sessions.py", line 589, in request
    resp = self.send(prep, **send_kwargs)
  File "/Library/Frameworks/Python.framework/Versions/3.13/lib/python3.13/site-packages/requests/sessions.py", line 703, in send
    r = adapter.send(request, **kwargs)
  File "/Library/Frameworks/Python.framework/Versions/3.13/lib/python3.13/site-packages/requests/adapters.py", line 700, in send
    raise ConnectionError(e, request=request)
requests.exceptions.ConnectionError: HTTPSConnectionPool(host='api.wandb.ai', port=443): Max retries exceeded with url: /graphql (Caused by NewConnectionError('<urllib3.connection.HTTPSConnection object at 0x1339aca50>: Failed to establish a new connection: [Errno 51] Network is unreachable'))
2025-06-20 22:40:52,664 INFO    MainThread:83605 [wandb_init.py:init():1032] starting run threads in backend
2025-06-20 22:40:52,852 INFO    MainThread:83605 [wandb_run.py:_console_start():2453] atexit reg
2025-06-20 22:40:52,853 INFO    MainThread:83605 [wandb_run.py:_redirect():2301] redirect: wrap_raw
2025-06-20 22:40:52,853 INFO    MainThread:83605 [wandb_run.py:_redirect():2370] Wrapping output streams.
2025-06-20 22:40:52,853 INFO    MainThread:83605 [wandb_run.py:_redirect():2393] Redirects installed.
2025-06-20 22:40:52,855 INFO    MainThread:83605 [wandb_init.py:init():1078] run started, returning control to user process
2025-06-20 22:40:54,767 INFO    MainThread:83605 [wandb_run.py:_finish():2219] finishing run aviv275-ie-university/mlops-project/et35wpbk
2025-06-20 22:40:54,767 INFO    MainThread:83605 [wandb_run.py:_atexit_cleanup():2418] got exitcode: 0
2025-06-20 22:40:54,768 INFO    MainThread:83605 [wandb_run.py:_restore():2400] restore
2025-06-20 22:40:54,768 INFO    MainThread:83605 [wandb_run.py:_restore():2406] restore done
2025-06-20 22:40:55,662 INFO    MainThread:83605 [wandb_run.py:_footer_history_summary_info():4000] rendering history
2025-06-20 22:40:55,662 INFO    MainThread:83605 [wandb_run.py:_footer_history_summary_info():4032] rendering summary
2025-06-20 22:40:55,662 INFO    MainThread:83605 [wandb_run.py:_footer_sync_info():3961] logging synced files
